Workbook

Sheet Assumptions
A1: RealShare — Financial Model
A2: Blue = editable input · Yellow = market data (verify w/ broker) · Black = calculated · Green = link to another sheet.
A3: Parameter | B3: Sym | C3: Value | D3: Unit | E3: Range | F3: Conf. | G3: Source / Note
A4: PROPERTY
A5: Apartment size | B5: m² | C5: 50 | D5: m² | E5: 38–70 | F5: Med | G5: inner-district 1–2BR
A6: Price per m² | C6: 3000 | D6: EUR/m² | E6: 2,400–4,200 | F6: Med | G6: districts V/VI/VII/IX/XIII — verify (M1)
A7: Property price | B7: P | C7: =C5*C6 | D7: EUR | E7: 108k–236k | F7: — | G7: =size × €/m²
A8: Gross rental yield | B8: y_g | C8: 0.05 | D8: % value/yr | E8: 4.0–6.5% | F8: Med | G8: verify (M2)
A9: Gross annual rent | B9: R_g | C9: =C7*C8 | D9: EUR/yr | F9: — | G9: =P × y_g
A10: Tokens per property | B10: N | C10: 2000 | D10: tokens | F10: TBD | G10: design choice
A11: Token price | B11: p_t | C11: =C7/C10 | D11: EUR/token | F11: — | G11: =P / N
A13: DEDUCTIONS — % of gross rent
A14: PM company fee | B14: d_pm | C14: 0.1 | D14: % rent | E14: 8–15% | F14: Med | G14: verify (M3)
A15: Letting / turnover (amortized) | C15: 0.04 | D15: % rent | E15: ~4% | F15: Med | G15: ~½ month rent / yr
A16: Maintenance + reserve | B16: d_mr | C16: 0.05 | D16: % rent | E16: 5%+ | F16: Med | G16: capex on old stock — verify
A17: Vacancy | B17: v | C17: 0.05 | D17: % rent | E17: 3–10% | F17: Med | G17: verify (M4)
A18: RealShare mgmt skim | B18: f_m | C18: 0.07 | D18: % rent | E18: 3–12% | F18: TBD | G18: RealShare lever (DEC-08)
A19: Subtotal — % deductions | C19: =SUM(C14:C18) | D19: % rent | F19: —
A21: DEDUCTIONS — fixed €/yr
A22: Property tax (municipal) | C22: 0 | D22: EUR/yr | E22: 0–139 | F22: High | G22: inner residential usually EXEMT
A23: Common charge (közös költség) | C23: 600 | D23: EUR/yr | E23: 300–1,500 | F23: Med | G23: building service charge — verify per bldg
A24: Insurance | C24: 200 | D24: EUR/yr | E24: 120–400 | F24: Med | G24: landlord cover — verify
A25: Subtotal — fixed €/yr | C25: =SUM(C22:C24) | D25: EUR/yr | F25: —
A27: CORPORATE TAX (if held in a Hungarian Kft.)
A28: Hungarian CIT rate | C28: 0.09 | D28: % net profit | E28: 9% | F28: High | G28: lowest in EU
A30: PLATFORM FEES & TURNOVER
A31: Primary txn fee | B31: f_p | C31: 0.02 | D31: % of raise | E31: 1–3% | F31: TBD | G31: RealShare lever (DEC-08)
A32: Secondary txn fee | B32: f_s | C32: 0.02 | D32: % per trade | E32: 1–3% | F32: TBD | G32: lever (DEC-08)
A33: Annual secondary turnover | B33: τ | C33: 0.2 | D33: % value/yr | E33: 5–50% | F33: Low | G33: speculative
A35: DEAL / COSTS
A36: Acquisition costs | C36: 0.06 | D36: % of price | E36: 6% resale / 10.5% new | F36: High | G36: transfer duty 4% + notary/legal — capitalized into raise
A37: Onboarding / property | B37: C_on | C37: 2500 | D37: EUR one-time | E37: appraisal+Kft+listing | F37: Med | G37: Kft setup ~€1k + appraisal — verify (L6)
A38: Capitalize onboarding into raise? | C38: 0 | D38: 1=yes, 0=no | F38: — | G38: lever (I-03): 1 removes C_on from RealShare P&L
A39: Oversight / property / yr | B39: C_ov | C39: 1200 | D39: EUR/yr | E39: incl. Kft acct ~€600 | F39: Med | G39: ongoing investor-side admin
A40: Annual fixed-cost base | B40: F | C40: 500000 | D40: EUR/yr | E40: 300k–750k | F40: Low | G40: infra+dev+compliance+mktg+support
A42: FX
A43: EUR → ILS | C43: 3.95 | D43: ₪ per € | E43: 3.7–4.2 | F43: Low | G43: volatile — use live rate
A44: HUF → EUR (context) | C44: 395 | D44: HUF per € | E44: 380–415 | F44: Med | G44: rent collected in HUF
A46: PREMIUM (optional, light)
A47: Premium sub price | B47: s | C47: 8 | D47: EUR/mo | E47: 5–15 | F47: Low | G47: SaaS tier
...

Sheet Waterfall
A1: Per-Property Rental Waterfall
A2: Blue = editable input · Yellow = market data (verify w/ broker) · Black = calculated · Green = link to another sheet.
A3: Gross annual rent (R_g) | C3: =Assumptions!C9 | D3: EUR/yr | E3: =P × y_g
A4: % deduction | B4: Rate | C4: Amount (EUR/yr)
A5: PM company fee | B5: =Assumptions!C14 | C5: =$C$3*B5
A6: Letting/turnover | B6: =Assumptions!C15 | C6: =$C$3*B6
A7: Maintenance + reserve | B7: =Assumptions!C16 | C7: =$C$3*B7
A8: Vacancy | B8: =Assumptions!C17 | C8: =$C$3*B8
A9: RealShare skim | B9: =Assumptions!C18 | C9: =$C$3*B9
A10: Subtotal % deductions | B10: =SUM(B5:B9) | C10: =SUM(C5:C9)
A12: Fixed costs (€/yr)
A13: Property tax | C13: =Assumptions!C22
A14: Common charge (közös költség) | C14: =Assumptions!C23
A15: Insurance | C15: =Assumptions!C24
A16: Subtotal fixed costs | C16: =SUM(C13:C15)
A18: Net operating income (pre-CIT) | C18: =C3-C10-C16 | E18: =R_g − %ded − fixed
A19: Corporate tax (CIT) | C19: =Assumptions!C28*MAX(C18,0) | E19: 9% of net profit
A20: NET distributable to holders | C20: =C18-C19
A21: Monthly distributable | C21: =C20/12
A22: Effective NET yield (after CIT) | C22: =C20/Assumptions!C7 | E22: =net / P
A23: Monthly payout / token (EUR) | C23: =C21/Assumptions!C10
A24: Annual payout / token (EUR) | C24: =C20/Assumptions!C10
A25: Monthly payout / token (ILS) | C25: =C23*Assumptions!C43 | E25: =EUR/token × FX

Sheet UnitEconomics
A1: Platform Unit Economics (per funded property)
A2: Blue = editable input · Yellow = market data (verify w/ broker) · Black = calculated · Green = link to another sheet.
A3: Property price (P) | C3: =Assumptions!C7
A4: Gross annual rent (R_g) | C4: =Waterfall!C3
A6: DEAL / RAISE
A7: Acquisition costs | C7: =Assumptions!C7*Assumptions!C36 | E7: =P × acq% (capitalized into raise)
A8: Capitalized onboarding | C8: =Assumptions!C37*Assumptions!C38 | E8: if toggle = 1
A9: Total raise | C9: =C3+C7+C8 | E9: what investors fund
A11: REVENUE TO REALSHARE
A12: Primary fee (one-time) | C12: =C9*Assumptions!C31 | E12: =raise × f_p
A13: Mgmt-fee revenue (/yr) | C13: =C4*Assumptions!C18 | E13: =R_g × f_m
A14: Secondary revenue (/yr) | C14: =C3*Assumptions!C33*Assumptions!C32 | E14: =P × τ × f_s
A15: Year-1 revenue | C15: =C12+C13+C14
A16: Steady-state revenue (/yr) | C16: =C13+C14
A18: COSTS TO REALSHARE
A19: Onboarding (one-time) | C19: =Assumptions!C37*(1-Assumptions!C38) | E19: removed if Capitalize=1
A20: Oversight (/yr) | C20: =Assumptions!C39
A22: CONTRIBUTION MARGIN
A23: Year-1 CM | C23: =C15-C19-C20
A24: Steady-state CM (/yr) | C24: =C16-C20
A25: (negative Year-1 CM = RealShare subsidizes onboarding; try Capitalize=1 or f_p=3%)

Sheet BreakEven
A1: Break-even & Scaling
A2: Blue = editable input · Yellow = market data (verify w/ broker) · Black = calculated · Green = link to another sheet.
A3: Annual fixed-cost base (F) | C3: =Assumptions!C40
A4: Steady-state CM / property | C4: =UnitEconomics!C24
A5: Properties to break even (n*) | C5: =IF(C4>0,C3/C4,"CM<=0: never") | E5: =F / CM_ss
A6: AUM at break-even (EUR) | C6: =IF(C4>0,(C3/C4)*Assumptions!C7,"-")
A8: Properties to break even at different fixed-cost bases (current CM/property):
A9: Fixed-cost base (EUR) | B9: n* (properties)
A10: 300000 | B10: =IF($C$4>0,A10/$C$4,"-")
A11: 500000 | B11: =IF($C$4>0,A11/$C$4,"-")
A12: 750000 | B12: =IF($C$4>0,A12/$C$4,"-")

Sheet Sensitivity
A1: Sensitivity
A2: Blue = editable input · Yellow = market data (verify w/ broker) · Black = calculated · Green = link to another sheet.
A3: Vacancy -> NET yield
A4: Vacancy | B4: Net yield
A5: 0 | B5: =((Assumptions!C9*(1-((Assumptions!C14+Assumptions!C15+Assumptions!C16+Assumptions!C18)+A5)))-Assumptions!C25)*(1-Assumptions!C28)/Assumptions!C7
A6: 0.05 | B6: =((Assumptions!C9*(1-((Assumptions!C14+Assumptions!C15+Assumptions!C16+Assumptions!C18)+A6)))-Assumptions!C25)*(1-Assumptions!C28)/Assumptions!C7
A7: 0.1 | B7: =((Assumptions!C9*(1-((Assumptions!C14+Assumptions!C15+Assumptions!C16+Assumptions!C18)+A7)))-Assumptions!C25)*(1-Assumptions!C28)/Assumptions!C7
A9: Gross yield -> NET yield
A10: Gross yield | B10: Net yield
A11: 0.04 | B11: =((Assumptions!C7*A11*(1-Assumptions!C19))-Assumptions!C25)*(1-Assumptions!C28)/Assumptions!C7
A12: 0.05 | B12: =((Assumptions!C7*A12*(1-Assumptions!C19))-Assumptions!C25)*(1-Assumptions!C28)/Assumptions!C7
A13: 0.065 | B13: =((Assumptions!C7*A13*(1-Assumptions!C19))-Assumptions!C25)*(1-Assumptions!C28)/Assumptions!C7
A15: Fee level -> Year-1 revenue / property
A16: Fee (f_p=f_s) | B16: Year-1 rev (EUR)
A17: 0.01 | B17: =(Assumptions!C7*(1+Assumptions!C36))*A17+Assumptions!C9*Assumptions!C18+Assumptions!C7*Assumptions!C33*A17
A18: 0.02 | B18: =(Assumptions!C7*(1+Assumptions!C36))*A18+Assumptions!C9*Assumptions!C18+Assumptions!C7*Assumptions!C33*A18
A19: 0.03 | B19: =(Assumptions!C7*(1+Assumptions!C36))*A19+Assumptions!C9*Assumptions!C18+Assumptions!C7*Assumptions!C33*A19
A21: FX (EUR->ILS) -> monthly ILS / token
A22: EUR->ILS | B22: ILS / token / mo
A23: 3.7 | B23: =Waterfall!C23*A23
A24: 3.95 | B24: =Waterfall!C23*A24
A25: 4.2 | B25: =Waterfall!C23*A25

Sheet STR
A1: Short-Term Rental (Airbnb) — FULL-COST Scenario & Comparison
A2: Cleaning folded into mgmt fee. REQUIRES a licence — VI banned new, V/VII restricted; green zone ~District XIII (DEC-09 / Q:S1-S4).
A4: STR PER-PROPERTY (annual)
A5: STR gross revenue | C5: =Assumptions!C54 | E5: =ADR × 365 × occ
A6: % deduction | B6: Rate | C6: Amount (EUR/yr)
A7: Platform/channel fee | B7: =Assumptions!C56 | C7: =$C$5*B7
A8: Tourism tax (IFA) | B8: =Assumptions!C57 | C8: =$C$5*B8
A9: Mgmt fee (incl. cleaning) | B9: =Assumptions!C58 | C9: =$C$5*B9
A10: RealShare skim | B10: =Assumptions!C18 | C10: =$C$5*B10
A11: Subtotal % deductions | B11: =SUM(B7:B10) | C11: =SUM(C7:C10)
A13: Fixed costs (€/yr)
A14: Utilities + internet | C14: =Assumptions!C61
A15: Furnishing (amortized) | C15: =Assumptions!C62
A16: STR insurance | C16: =Assumptions!C63
A17: Maintenance / wear | C17: =Assumptions!C64
A18: Building tax uplift | C18: =Assumptions!C65
A19: Common charge (közös) | C19: =Assumptions!C23
A20: Subtotal fixed | C20: =SUM(C14:C19)
A21: Net operating income (pre-CIT) | C21: =C5-C11-C20
A22: Corporate tax (CIT 9%) | C22: =Assumptions!C28*MAX(C21,0)
A23: NET distributable to holders | C23: =C21-C22
A24: Effective NET yield (after CIT) | C24: =C23/Assumptions!C7
A25: Monthly payout / token (ILS) | C25: =((C23/12)/Assumptions!C10)*Assumptions!C43
A27: COMPARISON: STR vs LONG-TERM
A28: Long-term net yield | C28: =Waterfall!C22
A29: STR net yield | C29: =C24
A30: Uplift (STR - LT) | C30: =C29-C28 | E30: pts — modest unless ADR & occ are high
A32: REALSHARE ECONOMICS UNDER STR
A33: Mgmt-skim revenue (/yr) | C33: =C5*Assumptions!C18 | E33: =STR gross × f_m
A34: Secondary revenue (/yr) | C34: =Assumptions!C7*Assumptions!C33*Assumptions!C32
A35: Steady-state revenue (/yr) | C35: =C33+C34
A36: Oversight (STR, /yr) | C36: =Assumptions!C66
A37: Steady-state CM (/yr) | C37: =C35-C36 | E37: RealShare gains from the bigger top line
A38: Long-term steady-state CM (/yr) | C38: =UnitEconomics!C24
A40: STR net yield by ADR × occupancy (it only beats LT at high ADR+occ)
A41: ADR \ Occ | B41: 0.55 | C41: 0.65 | D41: 0.75
A42: 70 | B42: =((($A42*365*B$41)*(1-(Assumptions!C56+Assumptions!C57+Assumptions!C58+Assumptions!C18)))-(Assumptions!C61+Assumptions!C62+Assumptions!C63+Assumptions!C64+Assumptions!C65+Assumptions!C23))*(1-Assumptions!C28)/Assumptions!C7 | C42: =((($A42*365*C$41)*(1-(Assumptions!C56+Assumptions!C57+Assumptions!C58+Assumptions!C18)))-(Assumptions!C61+Assumptions!C62+Assumptions!C63+Assumptions!C64+Assumptions!C65+Assumptions!C23))*(1-Assumptions!C28)/Assumptions!C7 | D42: =((($A42*365*D$41)*(1-(Assumptions!C56+Assumptions!C57+Assumptions!C58+Assumptions!C18)))-(Assumptions!C61+Assumptions!C62+Assumptions!C63+Assumptions!C64+Assumptions!C65+Assumptions!C23))*(1-Assumptions!C28)/Assumptions!C7
A43: 90 | B43: =((($A43*365*B$41)*(1-(Assumptions!C56+Assumptions!C57+Assumptions!C58+Assumptions!C18)))-(Assumptions!C61+Assumptions!C62+Assumptions!C63+Assumptions!C64+Assumptions!C65+Assumptions!C23))*(1-Assumptions!C28)/Assumptions!C7 | C43: =((($A43*365*C$41)*(1-(Assumptions!C56+Assumptions!C57+Assumptions!C58+Assumptions!C18)))-(Assumptions!C61+Assumptions!C62+Assumptions!C63+Assumptions!C64+Assumptions!C65+Assumptions!C23))*(1-Assumptions!C28)/Assumptions!C7 | D43: =((($A43*365*D$41)*(1-(Assumptions!C56+Assumptions!C57+Assumptions!C58+Assumptions!C18)))-(Assumptions!C61+Assumptions!C62+Assumptions!C63+Assumptions!C64+Assumptions!C65+Assumptions!C23))*(1-Assumptions!C28)/Assumptions!C7
A44: 110 | B44: =((($A44*365*B$41)*(1-(Assumptions!C56+Assumptions!C57+Assumptions!C58+Assumptions!C18)))-(Assumptions!C61+Assumptions!C62+Assumptions!C63+Assumptions!C64+Assumptions!C65+Assumptions!C23))*(1-Assumptions!C28)/Assumptions!C7 | C44: =((($A44*365*C$41)*(1-(Assumptions!C56+Assumptions!C57+Assumptions!C58+Assumptions!C18)))-(Assumptions!C61+Assumptions!C62+Assumptions!C63+Assumptions!C64+Assumptions!C65+Assumptions!C23))*(1-Assumptions!C28)/Assumptions!C7 | D44: =((($A44*365*D$41)*(1-(Assumptions!C56+Assumptions!C57+Assumptions!C58+Assumptions!C18)))-(Assumptions!C61+Assumptions!C62+Assumptions!C63+Assumptions!C64+Assumptions!C65+Assumptions!C23))*(1-Assumptions!C28)/Assumptions!C7
